Traceback (most recent call last):
  File "/root/miniconda3/lib/python3.8/site-packages/pandas/core/indexes/base.py", line 3080, in get_loc
    return self._engine.get_loc(casted_key)
  File "pandas/_libs/index.pyx", line 70, in pandas._libs.index.IndexEngine.get_loc
  File "pandas/_libs/index.pyx", line 101, in pandas._libs.index.IndexEngine.get_loc
  File "pandas/_libs/hashtable_class_helper.pxi", line 4554, in pandas._libs.hashtable.PyObjectHashTable.get_item
  File "pandas/_libs/hashtable_class_helper.pxi", line 4562, in pandas._libs.hashtable.PyObjectHashTable.get_item
KeyError: 'sub_index'
The above exception was the direct cause of the following exception:
Traceback (most recent call last):
  File "train.py", line 214, in <module>
    train(args)
  File "train.py", line 100, in train
    for batch_idx, (data, target) in enumerate(train_loader):
  File "/root/miniconda3/lib/python3.8/site-packages/torch/utils/data/dataloader.py", line 530, in __next__
    data = self._next_data()
  File "/root/miniconda3/lib/python3.8/site-packages/torch/utils/data/dataloader.py", line 570, in _next_data
    data = self._dataset_fetcher.fetch(index)  # may raise StopIteration
  File "/root/miniconda3/lib/python3.8/site-packages/torch/utils/data/_utils/fetch.py", line 49, in fetch
    data = [self.dataset[idx] for idx in possibly_batched_index]
  File "/root/miniconda3/lib/python3.8/site-packages/torch/utils/data/_utils/fetch.py", line 49, in <listcomp>
    data = [self.dataset[idx] for idx in possibly_batched_index]
  File "/root/Code/Code/dataset.py", line 21, in __getitem__
    file_path = f'''{OUTPUT_PATH}/preprocessed/{sub_dir}/{meta['seriesuid']}_{meta['sub_index']}.npy'''
  File "/root/miniconda3/lib/python3.8/site-packages/pandas/core/series.py", line 853, in __getitem__
    return self._get_value(key)
  File "/root/miniconda3/lib/python3.8/site-packages/pandas/core/series.py", line 961, in _get_value
    loc = self.index.get_loc(label)
  File "/root/miniconda3/lib/python3.8/site-packages/pandas/core/indexes/base.py", line 3082, in get_loc
    raise KeyError(key) from err
KeyError: 'sub_index'